<?xml version="1.0"?>
<robot xmlns:xacro="http://www.ros.org/wiki/xacro">

  <xacro:macro name="schunk_pg70" params="parent name *origin ">

    <joint name="${name}_base_joint" type="fixed">
      <parent link="${parent}" />
      <child link="${name}_base_link" />
      <xacro:insert_block name="origin" />
    </joint>

    <!-- BASE -->
    <link name="${name}_base_link">
      <inertial>
        <mass value="0.5"/>
        <origin xyz="0 0 0" rpy="0 0 0"/>
        <inertia ixx="1e-4" ixy="0" ixz="0"
                 iyy="1e-4" iyz="0"
                 izz="1e-4"/>
      </inertial>
      <visual>
        <geometry>
          <mesh filename="package://schunk_pg70/meshes/pg70.dae"/>
        </geometry>
        <material name="blue">
          <color rgba="0 0 1 1"/>
        </material>
      </visual>
      <collision>
        <geometry>
          <mesh filename="package://schunk_pg70/meshes/pg70.dae"/>
        </geometry>
      </collision>
    </link>

    <!-- LEFT FINGER BASE -->
    <joint name="${name}_finger_left_joint" type="prismatic">
      <parent link="${name}_base_link"/>
      <child link="${name}_finger_left_link"/>
      <limit effort="100" lower="-0.001" upper="0.04" velocity="2.0"/>
      <origin xyz="0 0 0.0789" rpy="0 0 0"/>
      <axis xyz="0 1 0"/>
    </joint>

    <link name="${name}_finger_left_link">
      <inertial>
        <mass value="0.05"/>
        <origin xyz="0 0 0" rpy="0 0 0"/>
        <inertia ixx="1e-5" ixy="0" ixz="0"
                 iyy="1e-5" iyz="0"
                 izz="1e-5"/>
      </inertial>
      <visual>
        <geometry>
          <box size="0.03 0.01 0.01"/>
        </geometry>
        <material name="black"/>
      </visual>
      <collision>
        <geometry>
          <box size="0.03 0.01 0.01"/>
        </geometry>
      </collision>
    </link>

    <!-- LEFT FINGERTIP -->
    <joint name="${name}_fingertip_left_joint" type="fixed">
      <parent link="${name}_finger_left_link"/>
      <child link="${name}_fingertip_left_link"/>
      <origin xyz="0 0.01 0.045" rpy="0 0 0"/>
    </joint>

    <link name="${name}_fingertip_left_link">
      <inertial>
        <mass value="0.02"/>
        <origin xyz="0 0 0" rpy="0 0 0"/>
        <inertia ixx="5e-6" ixy="0" ixz="0"
                 iyy="5e-6" iyz="0"
                 izz="5e-6"/>
      </inertial>
      <visual>
        <geometry>
          <box size="0.03 0.01 0.1"/>
        </geometry>
        <material name="silver"/>
      </visual>
      <collision>
        <geometry>
          <box size="0.03 0.01 0.1"/>
        </geometry>
      </collision>
    </link>

    <!-- RIGHT FINGER BASE -->
    <joint name="${name}_finger_right_joint" type="prismatic">
      <mimic joint="${name}_finger_left_joint" multiplier="1" offset="0"/>
      <parent link="${name}_base_link"/>
      <child link="${name}_finger_right_link"/>
      <limit effort="100" lower="-0.001" upper="0.04" velocity="2.0"/>
      <origin xyz="0 0 0.0789" rpy="0 0 0"/>
      <axis xyz="0 -1 0"/>
    </joint>

    <link name="${name}_finger_right_link">
      <inertial>
        <mass value="0.05"/>
        <origin xyz="0 0 0" rpy="0 0 0"/>
        <inertia ixx="1e-5" ixy="0" ixz="0"
                 iyy="1e-5" iyz="0"
                 izz="1e-5"/>
      </inertial>
      <visual>
        <geometry>
          <box size="0.03 0.01 0.01"/>
        </geometry>
        <material name="black"/>
      </visual>
      <collision>
        <geometry>
          <box size="0.03 0.01 0.01"/>
        </geometry>
      </collision>
    </link>

    <!-- RIGHT FINGERTIP -->
    <joint name="${name}_fingertip_right_joint" type="fixed">
      <parent link="${name}_finger_right_link"/>
      <child link="${name}_fingertip_right_link"/>
      <origin xyz="0 -0.01 0.045" rpy="0 0 0"/>
    </joint>

    <link name="${name}_fingertip_right_link">
      <inertial>
        <mass value="0.02"/>
        <origin xyz="0 0 0" rpy="0 0 0"/>
        <inertia ixx="5e-6" ixy="0" ixz="0"
                 iyy="5e-6" iyz="0"
                 izz="5e-6"/>
      </inertial>
      <visual>
        <geometry>
          <box size="0.03 0.01 0.1"/>
        </geometry>
        <material name="silver"/>
      </visual>
      <collision>
        <geometry>
          <box size="0.03 0.01 0.1"/>
        </geometry>
      </collision>
    </link>

    <!-- Transmissions -->
    <transmission name="${name}_finger_left_trans">
      <type>transmission_interface/SimpleTransmission</type>
      <joint name="${name}_finger_left_joint">
        <hardwareInterface>hardware_interface/EffortJointInterface</hardwareInterface>
      </joint>
      <actuator name="${name}_finger_left_motor">
        <mechanicalReduction>1</mechanicalReduction>
      </actuator>
    </transmission>

    <transmission name="${name}_finger_right_trans">
      <type>transmission_interface/SimpleTransmission</type>
      <joint name="${name}_finger_right_joint">
        <hardwareInterface>hardware_interface/EffortJointInterface</hardwareInterface>
      </joint>
      <actuator name="${name}_finger_right_motor">
        <mechanicalReduction>1</mechanicalReduction>
      </actuator>
    </transmission>

  </xacro:macro>
</robot>
